<mujoco model="legged_robot">
  <option timestep="0.002" gravity="0 0 -9.81"/>
  
  <worldbody>
    <geom name="floor" type="plane" size="5 5 0.1" rgba="0.8 0.9 0.8 1"/>

    <body name="base" pos="0 0 0.3">
    
      <freejoint/>

      <geom type="box" size="0.05 0.05 0.02" rgba="0.3 0.3 0.3 1"/>

      <body name="leg" pos="0 0 0">
        <joint name="hip" type="hinge" axis="0 1 0" range="-30 30"/>
        <geom type="capsule" fromto="0 0 0 0 0 -0.12" size="0.01" rgba="0.2 0.6 0.2 1"/>
      </body>
    </body>
  </worldbody>
</mujoco>